<mujoco>
  <compiler angle="radian" meshdir="./mesh" texturedir="./texture" />
  <asset>
    <mesh name="finger" file="finger.obj" />
    <texture name="panda" file="panda.png" type="2d" />
    <material name="panda" texture="panda" shininess=".4" specular=".4" />
    <material name="panda_white" rgba="1 1 1 1" shininess="0.4" specular="0.4" />
  </asset>
  <default>
      <velocity kv="10" ctrllimited="true" ctrlrange="-1 1" forcelimited='true' forcerange='-10 10'/>
      <geom solref="0.002 1" solimp="0.95 0.99 0.001" conaffinity="1" friction="1.0 0.1 0.001" contype="1" condim="6" />
  </default>
  <worldbody>
    <body name="gripper">
      <body name="panda_leftfinger" pos="0 0 0.0584">
        <inertial pos="0 0 0" mass="1.5e-02" diaginertia="2.3749e-06 2.3749e-06 7.5e-07"/>
        <joint name="panda_finger_joint1" pos="0 0 0" axis="0 1 0" type="slide" limited="true" range="0 0.04" />
        <geom name="left_finger" type="mesh" material="panda" mesh="finger" />
        <site name="left_finger_ee" pos="0.0 0.0 0.05" />
      </body>
      <body name="panda_rightfinger" pos="0 0 0.0584" euler="0 0 3.1415">
        <inertial pos="0 0 0" mass="1.5e-02" diaginertia="2.3749e-06 2.3749e-06 7.5e-07"/>
        <joint name="panda_finger_joint2" pos="0 0 0" axis="0 1 0" type="slide" limited="true" range="0 0.04" />
        <geom name="right_finger" type="mesh" material="panda" mesh="finger" condim="1" />
        <site name="right_finger_ee" pos="0.0 0.0 0.05" />
      </body>
      <site name="gripper_ee" pos="0.0 0 0.1" quat="0.5 0.5 -0.5 0.5 "/>
    </body>
  </worldbody>
    <tendon>
        <fixed name="split">
            <joint joint="panda_finger_joint1" coef="1"/>
            <joint joint="panda_finger_joint2" coef="1"/>
        </fixed>
    </tendon>
    <actuator>
        <velocity name="finger_actuator" tendon="split" />
    </actuator>
  </mujoco>
