<mujoco>
  <compiler angle="radian" meshdir="./mesh" texturedir="./texture"/>

   <option impratio="10"/>


  <asset>
    <mesh name="link0" file="link0.obj" />
    <mesh name="link1" file="link1.obj" />
    <mesh name="link2" file="link2.obj" />
    <mesh name="link3" file="link3.obj" />
    <mesh name="link4" file="link4.obj" />
    <mesh name="link5" file="link5.obj" />
    <mesh name="link6" file="link6.obj" />
    <mesh name="link7" file="link7.obj" />
    <mesh name="hand" file="hand.obj" />
    <texture name="panda" file="panda.png" type="2d" />
    <material name="panda" texture="panda" shininess=".4" specular=".4" />
    <material name="panda_white" rgba="1 1 1 1" shininess="0.4" specular="0.4" />
    <material name="metal" rgba="0.58 0.58 0.58 1"/>
    <material name="silicone" rgba="0.1882 0.1882 0.1882 1"/>
    <material name="gray" rgba="0.4627 0.4627 0.4627 1"/>
    <material name="black" rgba="0.149 0.149 0.149 1"/>

    <mesh class="2f85" file="base_mount.stl"/>
    <mesh class="2f85" file="base.stl"/>
    <mesh class="2f85" file="driver.stl"/>
    <mesh class="2f85" file="coupler.stl"/>
    <mesh class="2f85" file="follower.stl"/>
    <mesh class="2f85" file="pad.stl"/>
    <mesh class="2f85" file="silicone_pad.stl"/>
    <mesh class="2f85" file="spring_link.stl"/>
  </asset>
  <default>
    <velocity kv="10" ctrllimited="true" ctrlrange="-3.1415928 3.1415928" forcelimited='true'/>
    <geom solref="0.002 1" solimp="0.95 0.99 0.001" conaffinity="1" friction="1.0 0.1 0.001" contype="1" condim="6" />

    <default class="2f85">
      <mesh scale="0.001 0.001 0.001"/>
      <general biastype="affine"/>

      <joint axis="1 0 0"/>
      <default class="driver">
        <joint range="0 0.8" armature="0.005" damping="0.1" solimplimit="0.95 0.99 0.001"
            solreflimit="0.005 1"/>
      </default>
      <default class="follower">
        <joint range="-0.872664 0.872664" pos="0 -0.018 0.0065" solimplimit="0.95 0.99 0.001"
            solreflimit="0.005 1"/>
      </default>
      <default class="spring_link">
        <joint range="-0.29670597283 0.8" stiffness="0.05" springref="2.62" damping="0.00125"/>
      </default>
      <default class="coupler">
        <joint range="-1.57 0" solimplimit="0.95 0.99 0.001" solreflimit="0.005 1"/>
      </default>

      <default class="visual">
        <geom type="mesh" contype="0" conaffinity="0" group="2"/>
      </default>
      <default class="collision">
        <geom type="mesh" group="3"/>
        <default class="pad_box1">
          <geom mass="0" type="box" pos="0 -0.0026 0.028125" size="0.011 0.004 0.009375"
              friction="0.7" solimp="0.95 0.99 0.001" solref="0.004 1" priority="1"
              rgba="0.55 0.55 0.55 1"/>
        </default>
        <default class="pad_box2">
          <geom mass="0" type="box" pos="0 -0.0026 0.009375" size="0.011 0.004 0.009375"
              friction="0.6" solimp="0.95 0.99 0.001" solref="0.004 1" priority="1"
              rgba="0.45 0.45 0.45 1"/>
        </default>
      </default>
    </default>
  </default>
  <worldbody>
    <body name="panda_link0">
      <site name="base_site" />
      <geom type="mesh" material="panda" mesh="link0" />
      <inertial pos="-4.1018e-02 -1.4e-04 4.9974e-02" mass="6.29769e-01" fullinertia="3.15e-03 3.88e-03 4.285e-03 8.2904e-07 1.5e-04 8.2299e-06" />
      <body name="panda_link1" pos="0 0 0.333">
        <inertial pos="3.875e-03 2.081e-03 -4.762e-02" mass="4.970684" fullinertia="7.0337e-01 7.0661e-01 9.1170e-03 -1.3900e-04 6.7720e-03 1.9169e-02" />
        <joint name="panda_joint1" pos="0 0 0" axis="0 0 1" limited="true" range="-2.8973 2.8973" damping="0.0665" frictionloss="0.2450" />
        <geom type="mesh" material="panda_white" mesh="link1" />
        <body name="panda_link2" pos="0 0 0" quat="0.707107 -0.707107 0 0">
          <inertial pos="-3.141e-03 -2.872e-02 3.495e-03" mass="0.646926" fullinertia="7.9620e-03 2.8110e-02 2.5995e-02 -3.9250e-03 1.0254e-02 7.0400e-04" />
          <joint name="panda_joint2" pos="0 0 0" axis="0 0 1" limited="true" range="-1.7628 1.7628" damping="0.1987" frictionloss="0.1523" />
          <geom type="mesh" material="panda_white" mesh="link2" />
          <body name="panda_link3" pos="0 -0.316 0" quat="0.707107 0.707107 0 0">
            <inertial pos="2.7518e-02 3.9252e-02 -6.6502e-02" mass="3.228604" fullinertia="3.7242e-02 3.6155e-02 1.0830e-02 -4.7610e-03 -1.1396e-02 -1.2805e-02" />
            <joint name="panda_joint3" pos="0 0 0" axis="0 0 1" limited="true" range="-2.8973 2.8973" damping="0.0399" frictionloss="0.1827" />
            <geom type="mesh" material="panda" mesh="link3" />
            <body name="panda_link4" pos="0.0825 0 0" quat="0.707107 0.707107 0 0">
              <inertial pos="-5.317e-02 1.04419e-01 2.7454e-02" mass="3.587895" fullinertia="2.5853e-02 1.9552e-02 2.8323e-02 7.7960e-03 -1.3320e-03 8.6410e-03" />
              <joint name="panda_joint4" pos="0 0 0" axis="0 0 1" limited="true" range="-3.0718 -0.0698" damping="0.2257" frictionloss="0.3591" />
              <geom type="mesh" material="panda" mesh="link4" />
              <body name="panda_link5" pos="-0.0825 0.384 0" quat="0.707107 -0.707107 0 0">
                <inertial pos="1.1953e-02 4.1065e-02 -3.8437e-02" mass="1.225946" fullinertia="3.5549e-02 2.9474e-02 8.6270e-03 -2.1170e-03 -4.0370e-03 2.2900e-04" />
                <joint name="panda_joint5" pos="0 0 0" axis="0 0 1" limited="true" range="-2.8973 2.8973" damping="0.1023" frictionloss="0.2669" />
                <geom type="mesh" material="panda" mesh="link5" />
                <body name="panda_link6" pos="0 0 0" quat="0.707107 0.707107 0 0">
                  <inertial pos="6.0149e-02 -1.4117e-02 -1.0517e-02" mass="1.666555 " fullinertia="1.9640e-03 4.3540e-03 5.4330e-03 1.0900e-04 -1.1580e-03 3.4100e-04" />
                  <joint name="panda_joint6" pos="0 0 0" axis="0 0 1" limited="true" range="-0.0175 3.7525" damping="-0.0132" frictionloss="0.1658" />
                  <geom type="mesh" material="panda" mesh="link6" />
                  <body name="panda_link7" pos="0.088 0 0" quat="0.707107 0.707107 0 0">
                    <inertial pos="1.0517e-02 -4.252e-03 6.1597e-02" mass="7.35522e-01" fullinertia="1.2516e-02 1.0027e-02 4.8150e-03 -4.2800e-04 -1.1960e-03 -7.4100e-04" />
                    <joint name="panda_joint7" pos="0 0 0" axis="0 0 1" limited="true" range="-2.8973 2.8973" damping="0.0638" frictionloss="1.2109" />
                    <geom type="mesh" material="panda" mesh="link7" />
                    <body name="panda_link8" pos="0 0 0.107">
                      
                      <body name="base_mount" pos="0 0 0.007" childclass="2f85">
                        <geom class="visual" mesh="base_mount" material="black"/>
                        <geom class="collision" mesh="base_mount"/>
                        <body name="base" pos="0 0 0.0038" quat="1 0 0 -1">
                          <inertial mass="0.777441" pos="0 -2.70394e-05 0.0354675" quat="1 -0.00152849 0 0"
                              diaginertia="0.000260285 0.000225381 0.000152708"/>
                          <geom class="visual" mesh="base" material="black"/>
                          <geom class="collision" mesh="base"/>
                          
                          
                          <site name="pinch_site" pos="0 0 0.145" euler="0 0 1.57079634" type="sphere" rgba="0.0 0.9 0.9 1" size="0.02"/>
                          <!-- Right-hand side 4-bar linkage -->
                          <body name="right_driver" pos="0 0.0306011 0.054904">
                            <inertial mass="0.00899563" pos="2.96931e-12 0.0177547 0.00107314"
                                quat="0.681301 0.732003 0 0" diaginertia="1.72352e-06 1.60906e-06 3.22006e-07"/>
                            <!-- <joint name="right_driver_joint" class="driver"/> -->
                            <geom class="visual" mesh="driver" material="gray"/>
                            <geom class="collision" mesh="driver"/>
                            <body name="right_coupler" pos="0 0.0315 -0.0041">
                              <inertial mass="0.0140974" pos="0 0.00301209 0.0232175"
                                  quat="0.705636 -0.0455904 0.0455904 0.705636"
                                  diaginertia="4.16206e-06 3.52216e-06 8.88131e-07"/>
                              <!-- <joint name="right_coupler_joint" class="coupler"/> -->
                              <geom class="visual" mesh="coupler" material="black"/>
                              <geom class="collision" mesh="coupler"/>
                            </body>
                          </body>
                          <body name="right_spring_link" pos="0 0.0132 0.0609">
                            <inertial mass="0.0221642" pos="-8.65005e-09 0.0181624 0.0212658"
                                quat="0.663403 -0.244737 0.244737 0.663403"
                                diaginertia="8.96853e-06 6.71733e-06 2.63931e-06"/>
                            <!-- <joint name="right_spring_link_joint" class="spring_link"/> -->
                            <geom class="visual" mesh="spring_link" material="black"/>
                            <geom class="collision" mesh="spring_link"/>
                            <body name="right_follower" pos="0 0.055 0.0375">
                              <inertial mass="0.0125222" pos="0 -0.011046 0.0124786" quat="1 0.1664 0 0"
                                  diaginertia="2.67415e-06 2.4559e-06 6.02031e-07"/>
                              <!-- <joint name="right_follower_joint" class="follower"/> -->
                              <geom class="visual" mesh="follower" material="black"/>
                              <geom class="collision" mesh="follower"/>
                              <body name="right_pad" pos="0 -0.0189 0.01352">
                                <geom class="pad_box1" name="right_pad1"/>
                                <geom class="pad_box2" name="right_pad2"/>
                                <inertial mass="0.0035" pos="0 -0.0025 0.0185" quat="0.707107 0 0 0.707107"
                                    diaginertia="4.73958e-07 3.64583e-07 1.23958e-07"/>
                                <geom class="visual" mesh="pad"/>
                                <body name="right_silicone_pad">
                                  <geom class="visual" mesh="silicone_pad" material="black"/>
                                </body>
                              </body>
                            </body>
                          </body>
                          <!-- Left-hand side 4-bar linkage -->
                          <body name="left_driver" pos="0 -0.0306011 0.054904" quat="0 0 0 1">
                            <inertial mass="0.00899563" pos="0 0.0177547 0.00107314" quat="0.681301 0.732003 0 0"
                                diaginertia="1.72352e-06 1.60906e-06 3.22006e-07"/>
                            <!-- <joint name="left_driver_joint" class="driver"/> -->
                            <geom class="visual" mesh="driver" material="gray"/>
                            <geom class="collision" mesh="driver"/>
                            <body name="left_coupler" pos="0 0.0315 -0.0041">
                              <inertial mass="0.0140974" pos="0 0.00301209 0.0232175"
                                  quat="0.705636 -0.0455904 0.0455904 0.705636"
                                  diaginertia="4.16206e-06 3.52216e-06 8.88131e-07"/>
                              <!-- <joint name="left_coupler_joint" class="coupler"/> -->
                              <geom class="visual" mesh="coupler" material="black"/>
                              <geom class="collision" mesh="coupler"/>
                            </body>
                          </body>
                          <body name="left_spring_link" pos="0 -0.0132 0.0609" quat="0 0 0 1">
                            <inertial mass="0.0221642" pos="-8.65005e-09 0.0181624 0.0212658"
                                quat="0.663403 -0.244737 0.244737 0.663403"
                                diaginertia="8.96853e-06 6.71733e-06 2.63931e-06"/>
                            <!-- <joint name="left_spring_link_joint" class="spring_link"/> -->
                            <geom class="visual" mesh="spring_link" material="black"/>
                            <geom class="collision" mesh="spring_link"/>
                            <body name="left_follower" pos="0 0.055 0.0375">
                              <inertial mass="0.0125222" pos="0 -0.011046 0.0124786" quat="1 0.1664 0 0"
                                  diaginertia="2.67415e-06 2.4559e-06 6.02031e-07"/>
                              <!-- <joint name="left_follower_joint" class="follower"/> -->
                              <geom class="visual" mesh="follower" material="black"/>
                              <geom class="collision" mesh="follower"/>
                              <body name="left_pad" pos="0 -0.0189 0.01352">
                                <geom class="pad_box1" name="left_pad1"/>
                                <geom class="pad_box2" name="left_pad2"/>
                                <inertial mass="0.0035" pos="0 -0.0025 0.0185" quat="1 0 0 1"
                                    diaginertia="4.73958e-07 3.64583e-07 1.23958e-07"/>
                                <geom class="visual" mesh="pad"/>
                                <body name="left_silicone_pad">
                                  <geom class="visual" mesh="silicone_pad" material="black"/>
                                </body>
                              </body>
                            </body>
                          </body>
                        </body>
                      </body>
<!--     
                      <body name="panda_hand" euler="0 0 -0.785398163397">
                        <inertial pos="-1e-02 0 3e-02" mass="7.3e-01" diaginertia="1e-03 2.5e-03 1.7e-03" />
                        <geom type="mesh" material="panda" mesh="hand" />
                        <site name="wrist_site" rgba="1 0 0 1" size="0.02"/>
                      </body> -->
                    </body>
                  </body>
                </body>
              </body>
            </body>
          </body>
        </body>
      </body>
    </body>
    
  </worldbody>
  <actuator>
    <velocity forcerange="-87 87" joint="panda_joint1" name="panda_joint1" />
    <velocity forcerange="-87 87" joint="panda_joint2" name="panda_joint2" />
    <velocity forcerange="-87 87" joint="panda_joint3" name="panda_joint3" />
    <velocity forcerange="-87 87" joint="panda_joint4" name="panda_joint4" />
    <velocity forcerange="-12 12" joint="panda_joint5" name="panda_joint5" />
    <velocity forcerange="-12 12" joint="panda_joint6" name="panda_joint6" />
    <velocity forcerange="-12 12" joint="panda_joint7" name="panda_joint7" />
    <!-- <general class="2f85" name="fingers_actuator" tendon="split" forcerange="-5 5"
        ctrlrange="0 255" gainprm="0.3137255 0 0" biasprm="0 -100 -10"/> -->
  </actuator>
   
   <contact>
    <exclude body1="base" body2="left_driver"/>
    <exclude body1="base" body2="right_driver"/>
    <exclude body1="base" body2="left_spring_link"/>
    <exclude body1="base" body2="right_spring_link"/>
    <exclude body1="right_coupler" body2="right_follower"/>
    <exclude body1="left_coupler" body2="left_follower"/>
  </contact>

  <!-- <tendon>
    <fixed name="split">
      <joint joint="right_driver_joint" coef="0.5"/>
      <joint joint="left_driver_joint" coef="0.5"/>
    </fixed>
  </tendon>

  <equality>
    <connect anchor="0 0 0" body1="right_follower" body2="right_coupler" solimp="0.95 0.99 0.001"
        solref="0.005 1"/>
    <connect anchor="0 0 0" body1="left_follower" body2="left_coupler" solimp="0.95 0.99 0.001"
        solref="0.005 1"/>
    <joint joint1="right_driver_joint" joint2="left_driver_joint" polycoef="0 1 0 0 0"
        solimp="0.95 0.99 0.001" solref="0.005 1"/>
  </equality> -->

</mujoco>
